<robot
  name="PoppyErgoJr">
  <link
    name="base_link">
    <visual>
      <origin
        xyz="0 0 0"
        rpy="0 0 0" />
      <geometry>
        <mesh
          filename="package://poppy_ergo_jr_description/meshes/base.dae" />
      </geometry>
      <material
        name="">
        <color
          rgba="0.752941176470588 0.752941176470588 0.752941176470588 1" />
      </material>
    </visual>
    <collision>
      <origin
        xyz="0 0 0"
        rpy="0 0 0" />
      <geometry>
        <mesh
          filename="package://poppy_ergo_jr_description/meshes/base.dae" />
      </geometry>
    </collision>
  </link>
  <link
    name="long_U">
    <visual>
      <origin
        xyz="0 0 0"
        rpy="0 0 0" />
      <geometry>
        <mesh
          filename="package://poppy_ergo_jr_description/meshes/long_U.dae" />
      </geometry>
      <material
        name="">
        <color
          rgba="1 1 1 1" />
      </material>
    </visual>
    <collision>
      <origin
        xyz="0 0 0"
        rpy="0 0 0" />
      <geometry>
        <mesh
          filename="package://poppy_ergo_jr_description/meshes/long_U.dae" />
      </geometry>
    </collision>
  </link>
  <joint
    name="m1"
    type="continuous">
    <origin
      xyz="0 0 0.0327993216120967"
      rpy="0 0 0" />
    <parent
      link="base_link" />
    <child
      link="long_U" />
    <axis
      xyz="0 0 1" />
  </joint>
  <link
    name="section_1">
    <visual>
      <origin
        xyz="0 0 0"
        rpy="0 1.5707963267949 0" />
      <geometry>
        <mesh
          filename="package://poppy_ergo_jr_description/meshes/section_1.dae" />
      </geometry>
      <material
        name="">
        <color
          rgba="0.752941176470588 0.752941176470588 0.752941176470588 1" />
      </material>
    </visual>
    <collision>
      <origin
        xyz="0 0 0"
        rpy="0 1.5707963267949 0" />
      <geometry>
        <mesh
          filename="package://poppy_ergo_jr_description/meshes/section_1.dae" />
      </geometry>
    </collision>
  </link>
  <joint
    name="m2"
    type="continuous">
    <origin
      xyz="0 0 0.0240006783879033"
      rpy="0 -1.5707963267949 0" />
    <parent
      link="long_U" />
    <child
      link="section_1" />
    <axis
      xyz="0 0 -1" />
  </joint>
  <link
    name="section_2">
    <visual>
      <origin
        xyz="0 0 0"
        rpy="0 1.5707963267949 0" />
      <geometry>
        <mesh
          filename="package://poppy_ergo_jr_description/meshes/section_2.dae" />
      </geometry>
      <material
        name="">
        <color
          rgba="0.752941176470588 0.752941176470588 0.752941176470588 1" />
      </material>
    </visual>
    <collision>
      <origin
        xyz="0 0 0"
        rpy="0 1.5707963267949 0" />
      <geometry>
        <mesh
          filename="package://poppy_ergo_jr_description/meshes/section_2.dae" />
      </geometry>
    </collision>
  </link>
  <joint
    name="m3"
    type="continuous">
    <origin
      xyz="0.054 0 0"
      rpy="0 0 0" />
    <parent
      link="section_1" />
    <child
      link="section_2" />
    <axis
      xyz="0 0 -1" />
  </joint>
  <link
    name="section_3">
    <visual>
      <origin
        xyz="0 0 0"
        rpy="0 3.14159268 0" />
      <geometry>
        <mesh
          filename="package://poppy_ergo_jr_description/meshes/section_3.dae" />
      </geometry>
      <material
        name="">
        <color
          rgba="0.752941176470588 0.752941176470588 0.752941176470588 1" />
      </material>
    </visual>
    <collision>
      <origin
        xyz="0 0 0"
        rpy="0 3.14159268 0" />
      <geometry>
        <mesh
          filename="package://poppy_ergo_jr_description/meshes/section_3.dae" />
      </geometry>
    </collision>
  </link>
  <joint
    name="m4"
    type="continuous">
    <origin
      xyz="0.045 0 0"
      rpy="0 -1.5707963267949 0" />
    <parent
      link="section_2" />
    <child
      link="section_3" />
    <axis
      xyz="0 0 -1" />
  </joint>
  <link
    name="section_4">
    <visual>
      <origin
        xyz="0 -0.058 0"
        rpy="0 -1.5707963267949 0" />
      <geometry>
        <mesh
          filename="package://poppy_ergo_jr_description/meshes/section_4.dae" />
      </geometry>
      <material
        name="">
        <color
          rgba="0.752941176470588 0.752941176470588 0.752941176470588 1" />
      </material>
    </visual>
    <collision>
      <origin
        xyz="0 -0.058 0"
        rpy="0 -1.5707963267949 0" />
      <geometry>
        <mesh
          filename="package://poppy_ergo_jr_description/meshes/section_4.dae" />
      </geometry>
    </collision>
  </link>
  <joint
    name="m5"
    type="continuous">
    <origin
      xyz="0 -0.048 0"
      rpy="0 -1.5707963267949 0" />
    <parent
      link="section_3" />
    <child
      link="section_4" />
    <axis
      xyz="0 0 1" />
  </joint>
  <link
    name="tip">
    <visual>
      <origin
        xyz="0 0 0"
        rpy="0 0 0" />
      <geometry>
        <mesh
          filename="package://poppy_ergo_jr_description/meshes/gripper.dae" />
      </geometry>
      <material
        name="">
        <color
          rgba="0.752941176470588 0.752941176470588 0.752941176470588 1" />
      </material>
    </visual>
    <collision>
      <origin
        xyz="0 0 0"
        rpy="0 0 0" />
      <geometry>
        <mesh
          filename="package://poppy_ergo_jr_description/meshes/gripper.dae" />
      </geometry>
    </collision>
  </link>
  <joint
    name="m6"
    type="continuous">
    <origin
      xyz="0 -0.058 0"
      rpy="0 -1.5707963267949 0" />
    <parent
      link="section_4" />
    <child
      link="tip" />
    <axis
      xyz="0 0 1" />
  </joint>
</robot>

